# #7.7 login Test part I

## createAccount() - should fail on exception

- `exception`은 `await function`에서 발생 : rejected Promise 반환하기
  ```ts
  usersRepository.findOne.mockRejectedValue(new Error());
  ```
- 그 외 과정은 동일

## login() - should fail if user does not exist

- `login()`에서 해당 `email`로 `user`를 찾지 못해 실패하는 부분
  users.service.ts
  ```ts
  const user = await this.users.findOne(
    { email },
    { select: ['id', 'password'] },
  );
  if (!user) {
    return {
      ok: false,
      error: '해당 이메일이 존재하지 않습니다.',
    };
  }
  ```
  <br>
- `this.users.findOne()`에 대한 리턴값을 mock
  ```ts
  usersRepository.findOne.mockResolvedValue(null); // 못 찾으면 null
  ```
- 1회 호출되는지, 올바른 인자와 함께 호출되는지 검사
  ```ts
  expect(usersRepository.findOne).toHaveBeenCalledTimes(1);
  expect(usersRepository.findOne).toHaveBeenCalledWith(
    expect.any(Object),
    expect.any(Object),
  );
  ```

### 최종 코드

users.service.spec.ts

```ts
describe('login', () => {
  const loginArgs = { email: 'wha@te.ver', password: 'wha.tever' };
  it('should fail if user does not exist', async () => {
    usersRepository.findOne.mockResolvedValue(null);
    const result = await service.login(loginArgs);

    expect(usersRepository.findOne).toHaveBeenCalledTimes(1);
    expect(usersRepository.findOne).toHaveBeenCalledWith(
      expect.any(Object),
      expect.any(Object),
    );
    expect(result).toEqual({
      ok: false,
      error: '해당 이메일이 존재하지 않습니다.',
    });
  });
}
```

- `findOne()`의 기대(expect) 호출 횟수는 1회지만, 4회가 호출된 것으로 체크됨 (-> fail)
  - 다음 장에서 해결
